INFO - 2023-10-13 17:23:27,583 - process: 11640 - scheduler.py - gerapy.server.core.scheduler - 105 - scheduler - successfully synced task with jobs with force
INFO - 2023-10-13 17:24:03,274 - process: 11640 - build.py - gerapy.server.core.build - 24 - build - successfully build project spider to egg file C:\Users\admin\Desktop\Note\毕业设计\spiderProject\spiderweb\projects\spider\spider-1.0-py3.8.egg
ERROR - 2023-10-13 17:24:07,238 - process: 11640 - utils.py - gerapy.server.core.utils - 564 - utils - Traceback (most recent call last):
  File "D:\conda\envs\bishespider\lib\site-packages\redis\connection.py", line 264, in connect
    sock = self.retry.call_with_retry(
  File "D:\conda\envs\bishespider\lib\site-packages\redis\retry.py", line 46, in call_with_retry
    return do()
  File "D:\conda\envs\bishespider\lib\site-packages\redis\connection.py", line 265, in <lambda>
    lambda: self._connect(), lambda error: self.disconnect(error)
  File "D:\conda\envs\bishespider\lib\site-packages\redis\connection.py", line 627, in _connect
    raise err
  File "D:\conda\envs\bishespider\lib\site-packages\redis\connection.py", line 615, in _connect
    sock.connect(socket_address)
ConnectionRefusedError: [WinError 10061] 由于目标计算机积极拒绝，无法连接。

During handling of the above exception, another exception occurred:

Traceback (most recent call last):
  File "D:\conda\envs\bishespider\lib\runpy.py", line 194, in _run_module_as_main
    return _run_code(code, main_globals, None,
  File "D:\conda\envs\bishespider\lib\runpy.py", line 87, in _run_code
    exec(code, run_globals)
  File "D:\conda\envs\bishespider\lib\site-packages\scrapyd\runner.py", line 38, in <module>
    main()
  File "D:\conda\envs\bishespider\lib\site-packages\scrapyd\runner.py", line 34, in main
    execute()
  File "D:\conda\envs\bishespider\lib\site-packages\scrapy\cmdline.py", line 160, in execute
    cmd.crawler_process = CrawlerProcess(settings)
  File "D:\conda\envs\bishespider\lib\site-packages\scrapy\crawler.py", line 357, in __init__
    super().__init__(settings)
  File "D:\conda\envs\bishespider\lib\site-packages\scrapy\crawler.py", line 227, in __init__
    self.spider_loader = self._get_spider_loader(settings)
  File "D:\conda\envs\bishespider\lib\site-packages\scrapy\crawler.py", line 221, in _get_spider_loader
    return loader_cls.from_settings(settings.frozencopy())
  File "D:\conda\envs\bishespider\lib\site-packages\scrapy\spiderloader.py", line 79, in from_settings
    return cls(settings)
  File "D:\conda\envs\bishespider\lib\site-packages\scrapy\spiderloader.py", line 34, in __init__
    self._load_all_spiders()
  File "D:\conda\envs\bishespider\lib\site-packages\scrapy\spiderloader.py", line 63, in _load_all_spiders
    for module in walk_modules(name):
  File "D:\conda\envs\bishespider\lib\site-packages\scrapy\utils\misc.py", line 106, in walk_modules
    submod = import_module(fullpath)
  File "D:\conda\envs\bishespider\lib\importlib\__init__.py", line 127, in import_module
    return _bootstrap._gcd_import(name[level:], package, level)
  File "<frozen importlib._bootstrap>", line 1014, in _gcd_import
  File "<frozen importlib._bootstrap>", line 991, in _find_and_load
  File "<frozen importlib._bootstrap>", line 975, in _find_and_load_unlocked
  File "<frozen importlib._bootstrap>", line 655, in _load_unlocked
  File "<frozen importlib._bootstrap>", line 618, in _load_backward_compatible
  File "<frozen zipimport>", line 259, in load_module
  File "c:\users\admin\desktop\note\毕业设计\spiderproject\scrapyd\eggs\spider\1697189044.egg\tutorial\spiders\zhilian.py", line 14, in <module>
  File "c:\users\admin\desktop\note\毕业设计\spiderproject\scrapyd\eggs\spider\1697189044.egg\tutorial\spiders\zhilian.py", line 20, in TestSpider
  File "D:\conda\envs\bishespider\lib\site-packages\redis\commands\core.py", line 1829, in get
    return self.execute_command("GET", name)
  File "D:\conda\envs\bishespider\lib\site-packages\redis\client.py", line 533, in execute_command
    conn = self.connection or pool.get_connection(command_name, **options)
  File "D:\conda\envs\bishespider\lib\site-packages\redis\connection.py", line 1086, in get_connection
    connection.connect()
  File "D:\conda\envs\bishespider\lib\site-packages\redis\connection.py", line 270, in connect
    raise ConnectionError(self._error_message(e))
redis.exceptions.ConnectionError: Error 10061 connecting to 127.0.0.1:6379. 由于目标计算机积极拒绝，无法连接。.
Traceback (most recent call last):
  File "D:\conda\envs\bishespider\lib\site-packages\gerapy\server\core\utils.py", line 562, in wrapper
    result = func(*args, **kwargs)
  File "D:\conda\envs\bishespider\lib\site-packages\django\views\decorators\csrf.py", line 54, in wrapped_view
    return view_func(*args, **kwargs)
  File "D:\conda\envs\bishespider\lib\site-packages\django\views\generic\base.py", line 71, in view
    return self.dispatch(request, *args, **kwargs)
  File "D:\conda\envs\bishespider\lib\site-packages\rest_framework\views.py", line 509, in dispatch
    response = self.handle_exception(exc)
  File "D:\conda\envs\bishespider\lib\site-packages\rest_framework\views.py", line 469, in handle_exception
    self.raise_uncaught_exception(exc)
  File "D:\conda\envs\bishespider\lib\site-packages\rest_framework\views.py", line 480, in raise_uncaught_exception
    raise exc
  File "D:\conda\envs\bishespider\lib\site-packages\rest_framework\views.py", line 506, in dispatch
    response = handler(request, *args, **kwargs)
  File "D:\conda\envs\bishespider\lib\site-packages\rest_framework\decorators.py", line 50, in handler
    return func(*args, **kwargs)
  File "D:\conda\envs\bishespider\lib\site-packages\gerapy\server\core\views.py", line 461, in project_deploy
    scrapyd.add_version(project_name, int(time.time()), egg_file.read())
  File "D:\conda\envs\bishespider\lib\site-packages\scrapyd_api\wrapper.py", line 76, in add_version
    json = self.client.post(url, data=data, files=files,
  File "D:\conda\envs\bishespider\lib\site-packages\requests\sessions.py", line 637, in post
    return self.request("POST", url, data=data, json=json, **kwargs)
  File "D:\conda\envs\bishespider\lib\site-packages\scrapyd_api\client.py", line 38, in request
    return self._handle_response(response)
  File "D:\conda\envs\bishespider\lib\site-packages\scrapyd_api\client.py", line 34, in _handle_response
    raise ScrapydResponseError(json['message'])
scrapyd_api.exceptions.ScrapydResponseError: Traceback (most recent call last):
  File "D:\conda\envs\bishespider\lib\site-packages\redis\connection.py", line 264, in connect
    sock = self.retry.call_with_retry(
  File "D:\conda\envs\bishespider\lib\site-packages\redis\retry.py", line 46, in call_with_retry
    return do()
  File "D:\conda\envs\bishespider\lib\site-packages\redis\connection.py", line 265, in <lambda>
    lambda: self._connect(), lambda error: self.disconnect(error)
  File "D:\conda\envs\bishespider\lib\site-packages\redis\connection.py", line 627, in _connect
    raise err
  File "D:\conda\envs\bishespider\lib\site-packages\redis\connection.py", line 615, in _connect
    sock.connect(socket_address)
ConnectionRefusedError: [WinError 10061] 由于目标计算机积极拒绝，无法连接。

During handling of the above exception, another exception occurred:

Traceback (most recent call last):
  File "D:\conda\envs\bishespider\lib\runpy.py", line 194, in _run_module_as_main
    return _run_code(code, main_globals, None,
  File "D:\conda\envs\bishespider\lib\runpy.py", line 87, in _run_code
    exec(code, run_globals)
  File "D:\conda\envs\bishespider\lib\site-packages\scrapyd\runner.py", line 38, in <module>
    main()
  File "D:\conda\envs\bishespider\lib\site-packages\scrapyd\runner.py", line 34, in main
    execute()
  File "D:\conda\envs\bishespider\lib\site-packages\scrapy\cmdline.py", line 160, in execute
    cmd.crawler_process = CrawlerProcess(settings)
  File "D:\conda\envs\bishespider\lib\site-packages\scrapy\crawler.py", line 357, in __init__
    super().__init__(settings)
  File "D:\conda\envs\bishespider\lib\site-packages\scrapy\crawler.py", line 227, in __init__
    self.spider_loader = self._get_spider_loader(settings)
  File "D:\conda\envs\bishespider\lib\site-packages\scrapy\crawler.py", line 221, in _get_spider_loader
    return loader_cls.from_settings(settings.frozencopy())
  File "D:\conda\envs\bishespider\lib\site-packages\scrapy\spiderloader.py", line 79, in from_settings
    return cls(settings)
  File "D:\conda\envs\bishespider\lib\site-packages\scrapy\spiderloader.py", line 34, in __init__
    self._load_all_spiders()
  File "D:\conda\envs\bishespider\lib\site-packages\scrapy\spiderloader.py", line 63, in _load_all_spiders
    for module in walk_modules(name):
  File "D:\conda\envs\bishespider\lib\site-packages\scrapy\utils\misc.py", line 106, in walk_modules
    submod = import_module(fullpath)
  File "D:\conda\envs\bishespider\lib\importlib\__init__.py", line 127, in import_module
    return _bootstrap._gcd_import(name[level:], package, level)
  File "<frozen importlib._bootstrap>", line 1014, in _gcd_import
  File "<frozen importlib._bootstrap>", line 991, in _find_and_load
  File "<frozen importlib._bootstrap>", line 975, in _find_and_load_unlocked
  File "<frozen importlib._bootstrap>", line 655, in _load_unlocked
  File "<frozen importlib._bootstrap>", line 618, in _load_backward_compatible
  File "<frozen zipimport>", line 259, in load_module
  File "c:\users\admin\desktop\note\毕业设计\spiderproject\scrapyd\eggs\spider\1697189044.egg\tutorial\spiders\zhilian.py", line 14, in <module>
  File "c:\users\admin\desktop\note\毕业设计\spiderproject\scrapyd\eggs\spider\1697189044.egg\tutorial\spiders\zhilian.py", line 20, in TestSpider
  File "D:\conda\envs\bishespider\lib\site-packages\redis\commands\core.py", line 1829, in get
    return self.execute_command("GET", name)
  File "D:\conda\envs\bishespider\lib\site-packages\redis\client.py", line 533, in execute_command
    conn = self.connection or pool.get_connection(command_name, **options)
  File "D:\conda\envs\bishespider\lib\site-packages\redis\connection.py", line 1086, in get_connection
    connection.connect()
  File "D:\conda\envs\bishespider\lib\site-packages\redis\connection.py", line 270, in connect
    raise ConnectionError(self._error_message(e))
redis.exceptions.ConnectionError: Error 10061 connecting to 127.0.0.1:6379. 由于目标计算机积极拒绝，无法连接。.

ERROR - 2023-10-13 17:24:53,470 - process: 11640 - utils.py - gerapy.server.core.utils - 564 - utils - Traceback (most recent call last):
  File "D:\conda\envs\bishespider\lib\runpy.py", line 194, in _run_module_as_main
    return _run_code(code, main_globals, None,
  File "D:\conda\envs\bishespider\lib\runpy.py", line 87, in _run_code
    exec(code, run_globals)
  File "D:\conda\envs\bishespider\lib\site-packages\scrapyd\runner.py", line 38, in <module>
    main()
  File "D:\conda\envs\bishespider\lib\site-packages\scrapyd\runner.py", line 34, in main
    execute()
  File "D:\conda\envs\bishespider\lib\site-packages\scrapy\cmdline.py", line 160, in execute
    cmd.crawler_process = CrawlerProcess(settings)
  File "D:\conda\envs\bishespider\lib\site-packages\scrapy\crawler.py", line 357, in __init__
    super().__init__(settings)
  File "D:\conda\envs\bishespider\lib\site-packages\scrapy\crawler.py", line 227, in __init__
    self.spider_loader = self._get_spider_loader(settings)
  File "D:\conda\envs\bishespider\lib\site-packages\scrapy\crawler.py", line 221, in _get_spider_loader
    return loader_cls.from_settings(settings.frozencopy())
  File "D:\conda\envs\bishespider\lib\site-packages\scrapy\spiderloader.py", line 79, in from_settings
    return cls(settings)
  File "D:\conda\envs\bishespider\lib\site-packages\scrapy\spiderloader.py", line 34, in __init__
    self._load_all_spiders()
  File "D:\conda\envs\bishespider\lib\site-packages\scrapy\spiderloader.py", line 63, in _load_all_spiders
    for module in walk_modules(name):
  File "D:\conda\envs\bishespider\lib\site-packages\scrapy\utils\misc.py", line 106, in walk_modules
    submod = import_module(fullpath)
  File "D:\conda\envs\bishespider\lib\importlib\__init__.py", line 127, in import_module
    return _bootstrap._gcd_import(name[level:], package, level)
  File "<frozen importlib._bootstrap>", line 1014, in _gcd_import
  File "<frozen importlib._bootstrap>", line 991, in _find_and_load
  File "<frozen importlib._bootstrap>", line 975, in _find_and_load_unlocked
  File "<frozen importlib._bootstrap>", line 655, in _load_unlocked
  File "<frozen importlib._bootstrap>", line 618, in _load_backward_compatible
  File "<frozen zipimport>", line 259, in load_module
  File "c:\users\admin\desktop\note\毕业设计\spiderproject\scrapyd\eggs\spider\1697189092.egg\tutorial\spiders\zhilian.py", line 14, in <module>
  File "c:\users\admin\desktop\note\毕业设计\spiderproject\scrapyd\eggs\spider\1697189092.egg\tutorial\spiders\zhilian.py", line 20, in TestSpider
TypeError: int() argument must be a string, a bytes-like object or a number, not 'NoneType'
Traceback (most recent call last):
  File "D:\conda\envs\bishespider\lib\site-packages\gerapy\server\core\utils.py", line 562, in wrapper
    result = func(*args, **kwargs)
  File "D:\conda\envs\bishespider\lib\site-packages\django\views\decorators\csrf.py", line 54, in wrapped_view
    return view_func(*args, **kwargs)
  File "D:\conda\envs\bishespider\lib\site-packages\django\views\generic\base.py", line 71, in view
    return self.dispatch(request, *args, **kwargs)
  File "D:\conda\envs\bishespider\lib\site-packages\rest_framework\views.py", line 509, in dispatch
    response = self.handle_exception(exc)
  File "D:\conda\envs\bishespider\lib\site-packages\rest_framework\views.py", line 469, in handle_exception
    self.raise_uncaught_exception(exc)
  File "D:\conda\envs\bishespider\lib\site-packages\rest_framework\views.py", line 480, in raise_uncaught_exception
    raise exc
  File "D:\conda\envs\bishespider\lib\site-packages\rest_framework\views.py", line 506, in dispatch
    response = handler(request, *args, **kwargs)
  File "D:\conda\envs\bishespider\lib\site-packages\rest_framework\decorators.py", line 50, in handler
    return func(*args, **kwargs)
  File "D:\conda\envs\bishespider\lib\site-packages\gerapy\server\core\views.py", line 461, in project_deploy
    scrapyd.add_version(project_name, int(time.time()), egg_file.read())
  File "D:\conda\envs\bishespider\lib\site-packages\scrapyd_api\wrapper.py", line 76, in add_version
    json = self.client.post(url, data=data, files=files,
  File "D:\conda\envs\bishespider\lib\site-packages\requests\sessions.py", line 637, in post
    return self.request("POST", url, data=data, json=json, **kwargs)
  File "D:\conda\envs\bishespider\lib\site-packages\scrapyd_api\client.py", line 38, in request
    return self._handle_response(response)
  File "D:\conda\envs\bishespider\lib\site-packages\scrapyd_api\client.py", line 34, in _handle_response
    raise ScrapydResponseError(json['message'])
scrapyd_api.exceptions.ScrapydResponseError: Traceback (most recent call last):
  File "D:\conda\envs\bishespider\lib\runpy.py", line 194, in _run_module_as_main
    return _run_code(code, main_globals, None,
  File "D:\conda\envs\bishespider\lib\runpy.py", line 87, in _run_code
    exec(code, run_globals)
  File "D:\conda\envs\bishespider\lib\site-packages\scrapyd\runner.py", line 38, in <module>
    main()
  File "D:\conda\envs\bishespider\lib\site-packages\scrapyd\runner.py", line 34, in main
    execute()
  File "D:\conda\envs\bishespider\lib\site-packages\scrapy\cmdline.py", line 160, in execute
    cmd.crawler_process = CrawlerProcess(settings)
  File "D:\conda\envs\bishespider\lib\site-packages\scrapy\crawler.py", line 357, in __init__
    super().__init__(settings)
  File "D:\conda\envs\bishespider\lib\site-packages\scrapy\crawler.py", line 227, in __init__
    self.spider_loader = self._get_spider_loader(settings)
  File "D:\conda\envs\bishespider\lib\site-packages\scrapy\crawler.py", line 221, in _get_spider_loader
    return loader_cls.from_settings(settings.frozencopy())
  File "D:\conda\envs\bishespider\lib\site-packages\scrapy\spiderloader.py", line 79, in from_settings
    return cls(settings)
  File "D:\conda\envs\bishespider\lib\site-packages\scrapy\spiderloader.py", line 34, in __init__
    self._load_all_spiders()
  File "D:\conda\envs\bishespider\lib\site-packages\scrapy\spiderloader.py", line 63, in _load_all_spiders
    for module in walk_modules(name):
  File "D:\conda\envs\bishespider\lib\site-packages\scrapy\utils\misc.py", line 106, in walk_modules
    submod = import_module(fullpath)
  File "D:\conda\envs\bishespider\lib\importlib\__init__.py", line 127, in import_module
    return _bootstrap._gcd_import(name[level:], package, level)
  File "<frozen importlib._bootstrap>", line 1014, in _gcd_import
  File "<frozen importlib._bootstrap>", line 991, in _find_and_load
  File "<frozen importlib._bootstrap>", line 975, in _find_and_load_unlocked
  File "<frozen importlib._bootstrap>", line 655, in _load_unlocked
  File "<frozen importlib._bootstrap>", line 618, in _load_backward_compatible
  File "<frozen zipimport>", line 259, in load_module
  File "c:\users\admin\desktop\note\毕业设计\spiderproject\scrapyd\eggs\spider\1697189092.egg\tutorial\spiders\zhilian.py", line 14, in <module>
  File "c:\users\admin\desktop\note\毕业设计\spiderproject\scrapyd\eggs\spider\1697189092.egg\tutorial\spiders\zhilian.py", line 20, in TestSpider
TypeError: int() argument must be a string, a bytes-like object or a number, not 'NoneType'

ERROR - 2023-10-13 17:24:55,123 - process: 11640 - utils.py - gerapy.server.core.utils - 564 - utils - Traceback (most recent call last):
  File "D:\conda\envs\bishespider\lib\runpy.py", line 194, in _run_module_as_main
    return _run_code(code, main_globals, None,
  File "D:\conda\envs\bishespider\lib\runpy.py", line 87, in _run_code
    exec(code, run_globals)
  File "D:\conda\envs\bishespider\lib\site-packages\scrapyd\runner.py", line 38, in <module>
    main()
  File "D:\conda\envs\bishespider\lib\site-packages\scrapyd\runner.py", line 34, in main
    execute()
  File "D:\conda\envs\bishespider\lib\site-packages\scrapy\cmdline.py", line 160, in execute
    cmd.crawler_process = CrawlerProcess(settings)
  File "D:\conda\envs\bishespider\lib\site-packages\scrapy\crawler.py", line 357, in __init__
    super().__init__(settings)
  File "D:\conda\envs\bishespider\lib\site-packages\scrapy\crawler.py", line 227, in __init__
    self.spider_loader = self._get_spider_loader(settings)
  File "D:\conda\envs\bishespider\lib\site-packages\scrapy\crawler.py", line 221, in _get_spider_loader
    return loader_cls.from_settings(settings.frozencopy())
  File "D:\conda\envs\bishespider\lib\site-packages\scrapy\spiderloader.py", line 79, in from_settings
    return cls(settings)
  File "D:\conda\envs\bishespider\lib\site-packages\scrapy\spiderloader.py", line 34, in __init__
    self._load_all_spiders()
  File "D:\conda\envs\bishespider\lib\site-packages\scrapy\spiderloader.py", line 63, in _load_all_spiders
    for module in walk_modules(name):
  File "D:\conda\envs\bishespider\lib\site-packages\scrapy\utils\misc.py", line 106, in walk_modules
    submod = import_module(fullpath)
  File "D:\conda\envs\bishespider\lib\importlib\__init__.py", line 127, in import_module
    return _bootstrap._gcd_import(name[level:], package, level)
  File "<frozen importlib._bootstrap>", line 1014, in _gcd_import
  File "<frozen importlib._bootstrap>", line 991, in _find_and_load
  File "<frozen importlib._bootstrap>", line 975, in _find_and_load_unlocked
  File "<frozen importlib._bootstrap>", line 655, in _load_unlocked
  File "<frozen importlib._bootstrap>", line 618, in _load_backward_compatible
  File "<frozen zipimport>", line 259, in load_module
  File "c:\users\admin\desktop\note\毕业设计\spiderproject\scrapyd\eggs\spider\1697189094.egg\tutorial\spiders\zhilian.py", line 14, in <module>
  File "c:\users\admin\desktop\note\毕业设计\spiderproject\scrapyd\eggs\spider\1697189094.egg\tutorial\spiders\zhilian.py", line 20, in TestSpider
TypeError: int() argument must be a string, a bytes-like object or a number, not 'NoneType'
Traceback (most recent call last):
  File "D:\conda\envs\bishespider\lib\site-packages\gerapy\server\core\utils.py", line 562, in wrapper
    result = func(*args, **kwargs)
  File "D:\conda\envs\bishespider\lib\site-packages\django\views\decorators\csrf.py", line 54, in wrapped_view
    return view_func(*args, **kwargs)
  File "D:\conda\envs\bishespider\lib\site-packages\django\views\generic\base.py", line 71, in view
    return self.dispatch(request, *args, **kwargs)
  File "D:\conda\envs\bishespider\lib\site-packages\rest_framework\views.py", line 509, in dispatch
    response = self.handle_exception(exc)
  File "D:\conda\envs\bishespider\lib\site-packages\rest_framework\views.py", line 469, in handle_exception
    self.raise_uncaught_exception(exc)
  File "D:\conda\envs\bishespider\lib\site-packages\rest_framework\views.py", line 480, in raise_uncaught_exception
    raise exc
  File "D:\conda\envs\bishespider\lib\site-packages\rest_framework\views.py", line 506, in dispatch
    response = handler(request, *args, **kwargs)
  File "D:\conda\envs\bishespider\lib\site-packages\rest_framework\decorators.py", line 50, in handler
    return func(*args, **kwargs)
  File "D:\conda\envs\bishespider\lib\site-packages\gerapy\server\core\views.py", line 461, in project_deploy
    scrapyd.add_version(project_name, int(time.time()), egg_file.read())
  File "D:\conda\envs\bishespider\lib\site-packages\scrapyd_api\wrapper.py", line 76, in add_version
    json = self.client.post(url, data=data, files=files,
  File "D:\conda\envs\bishespider\lib\site-packages\requests\sessions.py", line 637, in post
    return self.request("POST", url, data=data, json=json, **kwargs)
  File "D:\conda\envs\bishespider\lib\site-packages\scrapyd_api\client.py", line 38, in request
    return self._handle_response(response)
  File "D:\conda\envs\bishespider\lib\site-packages\scrapyd_api\client.py", line 34, in _handle_response
    raise ScrapydResponseError(json['message'])
scrapyd_api.exceptions.ScrapydResponseError: Traceback (most recent call last):
  File "D:\conda\envs\bishespider\lib\runpy.py", line 194, in _run_module_as_main
    return _run_code(code, main_globals, None,
  File "D:\conda\envs\bishespider\lib\runpy.py", line 87, in _run_code
    exec(code, run_globals)
  File "D:\conda\envs\bishespider\lib\site-packages\scrapyd\runner.py", line 38, in <module>
    main()
  File "D:\conda\envs\bishespider\lib\site-packages\scrapyd\runner.py", line 34, in main
    execute()
  File "D:\conda\envs\bishespider\lib\site-packages\scrapy\cmdline.py", line 160, in execute
    cmd.crawler_process = CrawlerProcess(settings)
  File "D:\conda\envs\bishespider\lib\site-packages\scrapy\crawler.py", line 357, in __init__
    super().__init__(settings)
  File "D:\conda\envs\bishespider\lib\site-packages\scrapy\crawler.py", line 227, in __init__
    self.spider_loader = self._get_spider_loader(settings)
  File "D:\conda\envs\bishespider\lib\site-packages\scrapy\crawler.py", line 221, in _get_spider_loader
    return loader_cls.from_settings(settings.frozencopy())
  File "D:\conda\envs\bishespider\lib\site-packages\scrapy\spiderloader.py", line 79, in from_settings
    return cls(settings)
  File "D:\conda\envs\bishespider\lib\site-packages\scrapy\spiderloader.py", line 34, in __init__
    self._load_all_spiders()
  File "D:\conda\envs\bishespider\lib\site-packages\scrapy\spiderloader.py", line 63, in _load_all_spiders
    for module in walk_modules(name):
  File "D:\conda\envs\bishespider\lib\site-packages\scrapy\utils\misc.py", line 106, in walk_modules
    submod = import_module(fullpath)
  File "D:\conda\envs\bishespider\lib\importlib\__init__.py", line 127, in import_module
    return _bootstrap._gcd_import(name[level:], package, level)
  File "<frozen importlib._bootstrap>", line 1014, in _gcd_import
  File "<frozen importlib._bootstrap>", line 991, in _find_and_load
  File "<frozen importlib._bootstrap>", line 975, in _find_and_load_unlocked
  File "<frozen importlib._bootstrap>", line 655, in _load_unlocked
  File "<frozen importlib._bootstrap>", line 618, in _load_backward_compatible
  File "<frozen zipimport>", line 259, in load_module
  File "c:\users\admin\desktop\note\毕业设计\spiderproject\scrapyd\eggs\spider\1697189094.egg\tutorial\spiders\zhilian.py", line 14, in <module>
  File "c:\users\admin\desktop\note\毕业设计\spiderproject\scrapyd\eggs\spider\1697189094.egg\tutorial\spiders\zhilian.py", line 20, in TestSpider
TypeError: int() argument must be a string, a bytes-like object or a number, not 'NoneType'

ERROR - 2023-10-13 17:29:58,707 - process: 11640 - utils.py - gerapy.server.core.utils - 564 - utils - HTTPConnectionPool(host='127.0.0.1', port=6800): Read timed out. (read timeout=3)
Traceback (most recent call last):
  File "D:\conda\envs\bishespider\lib\site-packages\urllib3\connectionpool.py", line 466, in _make_request
    six.raise_from(e, None)
  File "<string>", line 3, in raise_from
  File "D:\conda\envs\bishespider\lib\site-packages\urllib3\connectionpool.py", line 461, in _make_request
    httplib_response = conn.getresponse()
  File "D:\conda\envs\bishespider\lib\http\client.py", line 1348, in getresponse
    response.begin()
  File "D:\conda\envs\bishespider\lib\http\client.py", line 316, in begin
    version, status, reason = self._read_status()
  File "D:\conda\envs\bishespider\lib\http\client.py", line 277, in _read_status
    line = str(self.fp.readline(_MAXLINE + 1), "iso-8859-1")
  File "D:\conda\envs\bishespider\lib\socket.py", line 669, in readinto
    return self._sock.recv_into(b)
socket.timeout: timed out

During handling of the above exception, another exception occurred:

Traceback (most recent call last):
  File "D:\conda\envs\bishespider\lib\site-packages\requests\adapters.py", line 486, in send
    resp = conn.urlopen(
  File "D:\conda\envs\bishespider\lib\site-packages\urllib3\connectionpool.py", line 798, in urlopen
    retries = retries.increment(
  File "D:\conda\envs\bishespider\lib\site-packages\urllib3\util\retry.py", line 550, in increment
    raise six.reraise(type(error), error, _stacktrace)
  File "D:\conda\envs\bishespider\lib\site-packages\urllib3\packages\six.py", line 770, in reraise
    raise value
  File "D:\conda\envs\bishespider\lib\site-packages\urllib3\connectionpool.py", line 714, in urlopen
    httplib_response = self._make_request(
  File "D:\conda\envs\bishespider\lib\site-packages\urllib3\connectionpool.py", line 468, in _make_request
    self._raise_timeout(err=e, url=url, timeout_value=read_timeout)
  File "D:\conda\envs\bishespider\lib\site-packages\urllib3\connectionpool.py", line 357, in _raise_timeout
    raise ReadTimeoutError(
urllib3.exceptions.ReadTimeoutError: HTTPConnectionPool(host='127.0.0.1', port=6800): Read timed out. (read timeout=3)

During handling of the above exception, another exception occurred:

Traceback (most recent call last):
  File "D:\conda\envs\bishespider\lib\site-packages\gerapy\server\core\utils.py", line 562, in wrapper
    result = func(*args, **kwargs)
  File "D:\conda\envs\bishespider\lib\site-packages\django\views\decorators\csrf.py", line 54, in wrapped_view
    return view_func(*args, **kwargs)
  File "D:\conda\envs\bishespider\lib\site-packages\django\views\generic\base.py", line 71, in view
    return self.dispatch(request, *args, **kwargs)
  File "D:\conda\envs\bishespider\lib\site-packages\rest_framework\views.py", line 509, in dispatch
    response = self.handle_exception(exc)
  File "D:\conda\envs\bishespider\lib\site-packages\rest_framework\views.py", line 469, in handle_exception
    self.raise_uncaught_exception(exc)
  File "D:\conda\envs\bishespider\lib\site-packages\rest_framework\views.py", line 480, in raise_uncaught_exception
    raise exc
  File "D:\conda\envs\bishespider\lib\site-packages\rest_framework\views.py", line 506, in dispatch
    response = handler(request, *args, **kwargs)
  File "D:\conda\envs\bishespider\lib\site-packages\rest_framework\decorators.py", line 50, in handler
    return func(*args, **kwargs)
  File "D:\conda\envs\bishespider\lib\site-packages\gerapy\server\core\views.py", line 120, in client_status
    requests.get(scrapyd_url(client.ip, client.port), timeout=3)
  File "D:\conda\envs\bishespider\lib\site-packages\requests\api.py", line 73, in get
    return request("get", url, params=params, **kwargs)
  File "D:\conda\envs\bishespider\lib\site-packages\requests\api.py", line 59, in request
    return session.request(method=method, url=url, **kwargs)
  File "D:\conda\envs\bishespider\lib\site-packages\requests\sessions.py", line 589, in request
    resp = self.send(prep, **send_kwargs)
  File "D:\conda\envs\bishespider\lib\site-packages\requests\sessions.py", line 703, in send
    r = adapter.send(request, **kwargs)
  File "D:\conda\envs\bishespider\lib\site-packages\requests\adapters.py", line 532, in send
    raise ReadTimeout(e, request=request)
requests.exceptions.ReadTimeout: HTTPConnectionPool(host='127.0.0.1', port=6800): Read timed out. (read timeout=3)
ERROR - 2023-10-13 17:30:17,795 - process: 11640 - utils.py - gerapy.server.core.utils - 564 - utils - HTTPConnectionPool(host='127.0.0.1', port=6800): Read timed out. (read timeout=3)
Traceback (most recent call last):
  File "D:\conda\envs\bishespider\lib\site-packages\urllib3\connectionpool.py", line 466, in _make_request
    six.raise_from(e, None)
  File "<string>", line 3, in raise_from
  File "D:\conda\envs\bishespider\lib\site-packages\urllib3\connectionpool.py", line 461, in _make_request
    httplib_response = conn.getresponse()
  File "D:\conda\envs\bishespider\lib\http\client.py", line 1348, in getresponse
    response.begin()
  File "D:\conda\envs\bishespider\lib\http\client.py", line 316, in begin
    version, status, reason = self._read_status()
  File "D:\conda\envs\bishespider\lib\http\client.py", line 277, in _read_status
    line = str(self.fp.readline(_MAXLINE + 1), "iso-8859-1")
  File "D:\conda\envs\bishespider\lib\socket.py", line 669, in readinto
    return self._sock.recv_into(b)
socket.timeout: timed out

During handling of the above exception, another exception occurred:

Traceback (most recent call last):
  File "D:\conda\envs\bishespider\lib\site-packages\requests\adapters.py", line 486, in send
    resp = conn.urlopen(
  File "D:\conda\envs\bishespider\lib\site-packages\urllib3\connectionpool.py", line 798, in urlopen
    retries = retries.increment(
  File "D:\conda\envs\bishespider\lib\site-packages\urllib3\util\retry.py", line 550, in increment
    raise six.reraise(type(error), error, _stacktrace)
  File "D:\conda\envs\bishespider\lib\site-packages\urllib3\packages\six.py", line 770, in reraise
    raise value
  File "D:\conda\envs\bishespider\lib\site-packages\urllib3\connectionpool.py", line 714, in urlopen
    httplib_response = self._make_request(
  File "D:\conda\envs\bishespider\lib\site-packages\urllib3\connectionpool.py", line 468, in _make_request
    self._raise_timeout(err=e, url=url, timeout_value=read_timeout)
  File "D:\conda\envs\bishespider\lib\site-packages\urllib3\connectionpool.py", line 357, in _raise_timeout
    raise ReadTimeoutError(
urllib3.exceptions.ReadTimeoutError: HTTPConnectionPool(host='127.0.0.1', port=6800): Read timed out. (read timeout=3)

During handling of the above exception, another exception occurred:

Traceback (most recent call last):
  File "D:\conda\envs\bishespider\lib\site-packages\gerapy\server\core\utils.py", line 562, in wrapper
    result = func(*args, **kwargs)
  File "D:\conda\envs\bishespider\lib\site-packages\django\views\decorators\csrf.py", line 54, in wrapped_view
    return view_func(*args, **kwargs)
  File "D:\conda\envs\bishespider\lib\site-packages\django\views\generic\base.py", line 71, in view
    return self.dispatch(request, *args, **kwargs)
  File "D:\conda\envs\bishespider\lib\site-packages\rest_framework\views.py", line 509, in dispatch
    response = self.handle_exception(exc)
  File "D:\conda\envs\bishespider\lib\site-packages\rest_framework\views.py", line 469, in handle_exception
    self.raise_uncaught_exception(exc)
  File "D:\conda\envs\bishespider\lib\site-packages\rest_framework\views.py", line 480, in raise_uncaught_exception
    raise exc
  File "D:\conda\envs\bishespider\lib\site-packages\rest_framework\views.py", line 506, in dispatch
    response = handler(request, *args, **kwargs)
  File "D:\conda\envs\bishespider\lib\site-packages\rest_framework\decorators.py", line 50, in handler
    return func(*args, **kwargs)
  File "D:\conda\envs\bishespider\lib\site-packages\gerapy\server\core\views.py", line 120, in client_status
    requests.get(scrapyd_url(client.ip, client.port), timeout=3)
  File "D:\conda\envs\bishespider\lib\site-packages\requests\api.py", line 73, in get
    return request("get", url, params=params, **kwargs)
  File "D:\conda\envs\bishespider\lib\site-packages\requests\api.py", line 59, in request
    return session.request(method=method, url=url, **kwargs)
  File "D:\conda\envs\bishespider\lib\site-packages\requests\sessions.py", line 589, in request
    resp = self.send(prep, **send_kwargs)
  File "D:\conda\envs\bishespider\lib\site-packages\requests\sessions.py", line 703, in send
    r = adapter.send(request, **kwargs)
  File "D:\conda\envs\bishespider\lib\site-packages\requests\adapters.py", line 532, in send
    raise ReadTimeout(e, request=request)
requests.exceptions.ReadTimeout: HTTPConnectionPool(host='127.0.0.1', port=6800): Read timed out. (read timeout=3)
ERROR - 2023-10-13 17:30:22,536 - process: 11640 - utils.py - gerapy.server.core.utils - 564 - utils - HTTPConnectionPool(host='127.0.0.1', port=6800): Read timed out. (read timeout=3)
Traceback (most recent call last):
  File "D:\conda\envs\bishespider\lib\site-packages\urllib3\connectionpool.py", line 466, in _make_request
    six.raise_from(e, None)
  File "<string>", line 3, in raise_from
  File "D:\conda\envs\bishespider\lib\site-packages\urllib3\connectionpool.py", line 461, in _make_request
    httplib_response = conn.getresponse()
  File "D:\conda\envs\bishespider\lib\http\client.py", line 1348, in getresponse
    response.begin()
  File "D:\conda\envs\bishespider\lib\http\client.py", line 316, in begin
    version, status, reason = self._read_status()
  File "D:\conda\envs\bishespider\lib\http\client.py", line 277, in _read_status
    line = str(self.fp.readline(_MAXLINE + 1), "iso-8859-1")
  File "D:\conda\envs\bishespider\lib\socket.py", line 669, in readinto
    return self._sock.recv_into(b)
socket.timeout: timed out

During handling of the above exception, another exception occurred:

Traceback (most recent call last):
  File "D:\conda\envs\bishespider\lib\site-packages\requests\adapters.py", line 486, in send
    resp = conn.urlopen(
  File "D:\conda\envs\bishespider\lib\site-packages\urllib3\connectionpool.py", line 798, in urlopen
    retries = retries.increment(
  File "D:\conda\envs\bishespider\lib\site-packages\urllib3\util\retry.py", line 550, in increment
    raise six.reraise(type(error), error, _stacktrace)
  File "D:\conda\envs\bishespider\lib\site-packages\urllib3\packages\six.py", line 770, in reraise
    raise value
  File "D:\conda\envs\bishespider\lib\site-packages\urllib3\connectionpool.py", line 714, in urlopen
    httplib_response = self._make_request(
  File "D:\conda\envs\bishespider\lib\site-packages\urllib3\connectionpool.py", line 468, in _make_request
    self._raise_timeout(err=e, url=url, timeout_value=read_timeout)
  File "D:\conda\envs\bishespider\lib\site-packages\urllib3\connectionpool.py", line 357, in _raise_timeout
    raise ReadTimeoutError(
urllib3.exceptions.ReadTimeoutError: HTTPConnectionPool(host='127.0.0.1', port=6800): Read timed out. (read timeout=3)

During handling of the above exception, another exception occurred:

Traceback (most recent call last):
  File "D:\conda\envs\bishespider\lib\site-packages\gerapy\server\core\utils.py", line 562, in wrapper
    result = func(*args, **kwargs)
  File "D:\conda\envs\bishespider\lib\site-packages\django\views\decorators\csrf.py", line 54, in wrapped_view
    return view_func(*args, **kwargs)
  File "D:\conda\envs\bishespider\lib\site-packages\django\views\generic\base.py", line 71, in view
    return self.dispatch(request, *args, **kwargs)
  File "D:\conda\envs\bishespider\lib\site-packages\rest_framework\views.py", line 509, in dispatch
    response = self.handle_exception(exc)
  File "D:\conda\envs\bishespider\lib\site-packages\rest_framework\views.py", line 469, in handle_exception
    self.raise_uncaught_exception(exc)
  File "D:\conda\envs\bishespider\lib\site-packages\rest_framework\views.py", line 480, in raise_uncaught_exception
    raise exc
  File "D:\conda\envs\bishespider\lib\site-packages\rest_framework\views.py", line 506, in dispatch
    response = handler(request, *args, **kwargs)
  File "D:\conda\envs\bishespider\lib\site-packages\rest_framework\decorators.py", line 50, in handler
    return func(*args, **kwargs)
  File "D:\conda\envs\bishespider\lib\site-packages\gerapy\server\core\views.py", line 120, in client_status
    requests.get(scrapyd_url(client.ip, client.port), timeout=3)
  File "D:\conda\envs\bishespider\lib\site-packages\requests\api.py", line 73, in get
    return request("get", url, params=params, **kwargs)
  File "D:\conda\envs\bishespider\lib\site-packages\requests\api.py", line 59, in request
    return session.request(method=method, url=url, **kwargs)
  File "D:\conda\envs\bishespider\lib\site-packages\requests\sessions.py", line 589, in request
    resp = self.send(prep, **send_kwargs)
  File "D:\conda\envs\bishespider\lib\site-packages\requests\sessions.py", line 703, in send
    r = adapter.send(request, **kwargs)
  File "D:\conda\envs\bishespider\lib\site-packages\requests\adapters.py", line 532, in send
    raise ReadTimeout(e, request=request)
requests.exceptions.ReadTimeout: HTTPConnectionPool(host='127.0.0.1', port=6800): Read timed out. (read timeout=3)
ERROR - 2023-10-13 17:30:41,167 - process: 11640 - utils.py - gerapy.server.core.utils - 564 - utils - HTTPConnectionPool(host='127.0.0.1', port=6800): Read timed out. (read timeout=3)
Traceback (most recent call last):
  File "D:\conda\envs\bishespider\lib\site-packages\urllib3\connectionpool.py", line 466, in _make_request
    six.raise_from(e, None)
  File "<string>", line 3, in raise_from
  File "D:\conda\envs\bishespider\lib\site-packages\urllib3\connectionpool.py", line 461, in _make_request
    httplib_response = conn.getresponse()
  File "D:\conda\envs\bishespider\lib\http\client.py", line 1348, in getresponse
    response.begin()
  File "D:\conda\envs\bishespider\lib\http\client.py", line 316, in begin
    version, status, reason = self._read_status()
  File "D:\conda\envs\bishespider\lib\http\client.py", line 277, in _read_status
    line = str(self.fp.readline(_MAXLINE + 1), "iso-8859-1")
  File "D:\conda\envs\bishespider\lib\socket.py", line 669, in readinto
    return self._sock.recv_into(b)
socket.timeout: timed out

During handling of the above exception, another exception occurred:

Traceback (most recent call last):
  File "D:\conda\envs\bishespider\lib\site-packages\requests\adapters.py", line 486, in send
    resp = conn.urlopen(
  File "D:\conda\envs\bishespider\lib\site-packages\urllib3\connectionpool.py", line 798, in urlopen
    retries = retries.increment(
  File "D:\conda\envs\bishespider\lib\site-packages\urllib3\util\retry.py", line 550, in increment
    raise six.reraise(type(error), error, _stacktrace)
  File "D:\conda\envs\bishespider\lib\site-packages\urllib3\packages\six.py", line 770, in reraise
    raise value
  File "D:\conda\envs\bishespider\lib\site-packages\urllib3\connectionpool.py", line 714, in urlopen
    httplib_response = self._make_request(
  File "D:\conda\envs\bishespider\lib\site-packages\urllib3\connectionpool.py", line 468, in _make_request
    self._raise_timeout(err=e, url=url, timeout_value=read_timeout)
  File "D:\conda\envs\bishespider\lib\site-packages\urllib3\connectionpool.py", line 357, in _raise_timeout
    raise ReadTimeoutError(
urllib3.exceptions.ReadTimeoutError: HTTPConnectionPool(host='127.0.0.1', port=6800): Read timed out. (read timeout=3)

During handling of the above exception, another exception occurred:

Traceback (most recent call last):
  File "D:\conda\envs\bishespider\lib\site-packages\gerapy\server\core\utils.py", line 562, in wrapper
    result = func(*args, **kwargs)
  File "D:\conda\envs\bishespider\lib\site-packages\django\views\decorators\csrf.py", line 54, in wrapped_view
    return view_func(*args, **kwargs)
  File "D:\conda\envs\bishespider\lib\site-packages\django\views\generic\base.py", line 71, in view
    return self.dispatch(request, *args, **kwargs)
  File "D:\conda\envs\bishespider\lib\site-packages\rest_framework\views.py", line 509, in dispatch
    response = self.handle_exception(exc)
  File "D:\conda\envs\bishespider\lib\site-packages\rest_framework\views.py", line 469, in handle_exception
    self.raise_uncaught_exception(exc)
  File "D:\conda\envs\bishespider\lib\site-packages\rest_framework\views.py", line 480, in raise_uncaught_exception
    raise exc
  File "D:\conda\envs\bishespider\lib\site-packages\rest_framework\views.py", line 506, in dispatch
    response = handler(request, *args, **kwargs)
  File "D:\conda\envs\bishespider\lib\site-packages\rest_framework\decorators.py", line 50, in handler
    return func(*args, **kwargs)
  File "D:\conda\envs\bishespider\lib\site-packages\gerapy\server\core\views.py", line 120, in client_status
    requests.get(scrapyd_url(client.ip, client.port), timeout=3)
  File "D:\conda\envs\bishespider\lib\site-packages\requests\api.py", line 73, in get
    return request("get", url, params=params, **kwargs)
  File "D:\conda\envs\bishespider\lib\site-packages\requests\api.py", line 59, in request
    return session.request(method=method, url=url, **kwargs)
  File "D:\conda\envs\bishespider\lib\site-packages\requests\sessions.py", line 589, in request
    resp = self.send(prep, **send_kwargs)
  File "D:\conda\envs\bishespider\lib\site-packages\requests\sessions.py", line 703, in send
    r = adapter.send(request, **kwargs)
  File "D:\conda\envs\bishespider\lib\site-packages\requests\adapters.py", line 532, in send
    raise ReadTimeout(e, request=request)
requests.exceptions.ReadTimeout: HTTPConnectionPool(host='127.0.0.1', port=6800): Read timed out. (read timeout=3)
ERROR - 2023-10-13 17:30:45,740 - process: 11640 - utils.py - gerapy.server.core.utils - 564 - utils - HTTPConnectionPool(host='127.0.0.1', port=6800): Read timed out. (read timeout=3)
Traceback (most recent call last):
  File "D:\conda\envs\bishespider\lib\site-packages\urllib3\connectionpool.py", line 466, in _make_request
    six.raise_from(e, None)
  File "<string>", line 3, in raise_from
  File "D:\conda\envs\bishespider\lib\site-packages\urllib3\connectionpool.py", line 461, in _make_request
    httplib_response = conn.getresponse()
  File "D:\conda\envs\bishespider\lib\http\client.py", line 1348, in getresponse
    response.begin()
  File "D:\conda\envs\bishespider\lib\http\client.py", line 316, in begin
    version, status, reason = self._read_status()
  File "D:\conda\envs\bishespider\lib\http\client.py", line 277, in _read_status
    line = str(self.fp.readline(_MAXLINE + 1), "iso-8859-1")
  File "D:\conda\envs\bishespider\lib\socket.py", line 669, in readinto
    return self._sock.recv_into(b)
socket.timeout: timed out

During handling of the above exception, another exception occurred:

Traceback (most recent call last):
  File "D:\conda\envs\bishespider\lib\site-packages\requests\adapters.py", line 486, in send
    resp = conn.urlopen(
  File "D:\conda\envs\bishespider\lib\site-packages\urllib3\connectionpool.py", line 798, in urlopen
    retries = retries.increment(
  File "D:\conda\envs\bishespider\lib\site-packages\urllib3\util\retry.py", line 550, in increment
    raise six.reraise(type(error), error, _stacktrace)
  File "D:\conda\envs\bishespider\lib\site-packages\urllib3\packages\six.py", line 770, in reraise
    raise value
  File "D:\conda\envs\bishespider\lib\site-packages\urllib3\connectionpool.py", line 714, in urlopen
    httplib_response = self._make_request(
  File "D:\conda\envs\bishespider\lib\site-packages\urllib3\connectionpool.py", line 468, in _make_request
    self._raise_timeout(err=e, url=url, timeout_value=read_timeout)
  File "D:\conda\envs\bishespider\lib\site-packages\urllib3\connectionpool.py", line 357, in _raise_timeout
    raise ReadTimeoutError(
urllib3.exceptions.ReadTimeoutError: HTTPConnectionPool(host='127.0.0.1', port=6800): Read timed out. (read timeout=3)

During handling of the above exception, another exception occurred:

Traceback (most recent call last):
  File "D:\conda\envs\bishespider\lib\site-packages\gerapy\server\core\utils.py", line 562, in wrapper
    result = func(*args, **kwargs)
  File "D:\conda\envs\bishespider\lib\site-packages\django\views\decorators\csrf.py", line 54, in wrapped_view
    return view_func(*args, **kwargs)
  File "D:\conda\envs\bishespider\lib\site-packages\django\views\generic\base.py", line 71, in view
    return self.dispatch(request, *args, **kwargs)
  File "D:\conda\envs\bishespider\lib\site-packages\rest_framework\views.py", line 509, in dispatch
    response = self.handle_exception(exc)
  File "D:\conda\envs\bishespider\lib\site-packages\rest_framework\views.py", line 469, in handle_exception
    self.raise_uncaught_exception(exc)
  File "D:\conda\envs\bishespider\lib\site-packages\rest_framework\views.py", line 480, in raise_uncaught_exception
    raise exc
  File "D:\conda\envs\bishespider\lib\site-packages\rest_framework\views.py", line 506, in dispatch
    response = handler(request, *args, **kwargs)
  File "D:\conda\envs\bishespider\lib\site-packages\rest_framework\decorators.py", line 50, in handler
    return func(*args, **kwargs)
  File "D:\conda\envs\bishespider\lib\site-packages\gerapy\server\core\views.py", line 120, in client_status
    requests.get(scrapyd_url(client.ip, client.port), timeout=3)
  File "D:\conda\envs\bishespider\lib\site-packages\requests\api.py", line 73, in get
    return request("get", url, params=params, **kwargs)
  File "D:\conda\envs\bishespider\lib\site-packages\requests\api.py", line 59, in request
    return session.request(method=method, url=url, **kwargs)
  File "D:\conda\envs\bishespider\lib\site-packages\requests\sessions.py", line 589, in request
    resp = self.send(prep, **send_kwargs)
  File "D:\conda\envs\bishespider\lib\site-packages\requests\sessions.py", line 703, in send
    r = adapter.send(request, **kwargs)
  File "D:\conda\envs\bishespider\lib\site-packages\requests\adapters.py", line 532, in send
    raise ReadTimeout(e, request=request)
requests.exceptions.ReadTimeout: HTTPConnectionPool(host='127.0.0.1', port=6800): Read timed out. (read timeout=3)
ERROR - 2023-10-13 17:30:52,693 - process: 11640 - utils.py - gerapy.server.core.utils - 564 - utils - ('Connection aborted.', ConnectionResetError(10054, '远程主机强迫关闭了一个现有的连接。', None, 10054, None))
Traceback (most recent call last):
  File "D:\conda\envs\bishespider\lib\site-packages\urllib3\connectionpool.py", line 714, in urlopen
    httplib_response = self._make_request(
  File "D:\conda\envs\bishespider\lib\site-packages\urllib3\connectionpool.py", line 466, in _make_request
    six.raise_from(e, None)
  File "<string>", line 3, in raise_from
  File "D:\conda\envs\bishespider\lib\site-packages\urllib3\connectionpool.py", line 461, in _make_request
    httplib_response = conn.getresponse()
  File "D:\conda\envs\bishespider\lib\http\client.py", line 1348, in getresponse
    response.begin()
  File "D:\conda\envs\bishespider\lib\http\client.py", line 316, in begin
    version, status, reason = self._read_status()
  File "D:\conda\envs\bishespider\lib\http\client.py", line 277, in _read_status
    line = str(self.fp.readline(_MAXLINE + 1), "iso-8859-1")
  File "D:\conda\envs\bishespider\lib\socket.py", line 669, in readinto
    return self._sock.recv_into(b)
ConnectionResetError: [WinError 10054] 远程主机强迫关闭了一个现有的连接。

During handling of the above exception, another exception occurred:

Traceback (most recent call last):
  File "D:\conda\envs\bishespider\lib\site-packages\requests\adapters.py", line 486, in send
    resp = conn.urlopen(
  File "D:\conda\envs\bishespider\lib\site-packages\urllib3\connectionpool.py", line 798, in urlopen
    retries = retries.increment(
  File "D:\conda\envs\bishespider\lib\site-packages\urllib3\util\retry.py", line 550, in increment
    raise six.reraise(type(error), error, _stacktrace)
  File "D:\conda\envs\bishespider\lib\site-packages\urllib3\packages\six.py", line 769, in reraise
    raise value.with_traceback(tb)
  File "D:\conda\envs\bishespider\lib\site-packages\urllib3\connectionpool.py", line 714, in urlopen
    httplib_response = self._make_request(
  File "D:\conda\envs\bishespider\lib\site-packages\urllib3\connectionpool.py", line 466, in _make_request
    six.raise_from(e, None)
  File "<string>", line 3, in raise_from
  File "D:\conda\envs\bishespider\lib\site-packages\urllib3\connectionpool.py", line 461, in _make_request
    httplib_response = conn.getresponse()
  File "D:\conda\envs\bishespider\lib\http\client.py", line 1348, in getresponse
    response.begin()
  File "D:\conda\envs\bishespider\lib\http\client.py", line 316, in begin
    version, status, reason = self._read_status()
  File "D:\conda\envs\bishespider\lib\http\client.py", line 277, in _read_status
    line = str(self.fp.readline(_MAXLINE + 1), "iso-8859-1")
  File "D:\conda\envs\bishespider\lib\socket.py", line 669, in readinto
    return self._sock.recv_into(b)
urllib3.exceptions.ProtocolError: ('Connection aborted.', ConnectionResetError(10054, '远程主机强迫关闭了一个现有的连接。', None, 10054, None))

During handling of the above exception, another exception occurred:

Traceback (most recent call last):
  File "D:\conda\envs\bishespider\lib\site-packages\gerapy\server\core\utils.py", line 562, in wrapper
    result = func(*args, **kwargs)
  File "D:\conda\envs\bishespider\lib\site-packages\django\views\decorators\csrf.py", line 54, in wrapped_view
    return view_func(*args, **kwargs)
  File "D:\conda\envs\bishespider\lib\site-packages\django\views\generic\base.py", line 71, in view
    return self.dispatch(request, *args, **kwargs)
  File "D:\conda\envs\bishespider\lib\site-packages\rest_framework\views.py", line 509, in dispatch
    response = self.handle_exception(exc)
  File "D:\conda\envs\bishespider\lib\site-packages\rest_framework\views.py", line 469, in handle_exception
    self.raise_uncaught_exception(exc)
  File "D:\conda\envs\bishespider\lib\site-packages\rest_framework\views.py", line 480, in raise_uncaught_exception
    raise exc
  File "D:\conda\envs\bishespider\lib\site-packages\rest_framework\views.py", line 506, in dispatch
    response = handler(request, *args, **kwargs)
  File "D:\conda\envs\bishespider\lib\site-packages\rest_framework\decorators.py", line 50, in handler
    return func(*args, **kwargs)
  File "D:\conda\envs\bishespider\lib\site-packages\gerapy\server\core\views.py", line 690, in job_list
    result = scrapyd.list_jobs(project_name)
  File "D:\conda\envs\bishespider\lib\site-packages\scrapyd_api\wrapper.py", line 139, in list_jobs
    jobs = self.client.get(url, params=params, timeout=self.timeout)
  File "D:\conda\envs\bishespider\lib\site-packages\requests\sessions.py", line 602, in get
    return self.request("GET", url, **kwargs)
  File "D:\conda\envs\bishespider\lib\site-packages\scrapyd_api\client.py", line 37, in request
    response = super(Client, self).request(*args, **kwargs)
  File "D:\conda\envs\bishespider\lib\site-packages\requests\sessions.py", line 589, in request
    resp = self.send(prep, **send_kwargs)
  File "D:\conda\envs\bishespider\lib\site-packages\requests\sessions.py", line 703, in send
    r = adapter.send(request, **kwargs)
  File "D:\conda\envs\bishespider\lib\site-packages\requests\adapters.py", line 501, in send
    raise ConnectionError(err, request=request)
requests.exceptions.ConnectionError: ('Connection aborted.', ConnectionResetError(10054, '远程主机强迫关闭了一个现有的连接。', None, 10054, None))
ERROR - 2023-10-13 17:30:52,693 - process: 11640 - utils.py - gerapy.server.core.utils - 564 - utils - ('Connection aborted.', ConnectionResetError(10054, '远程主机强迫关闭了一个现有的连接。', None, 10054, None))
Traceback (most recent call last):
  File "D:\conda\envs\bishespider\lib\site-packages\urllib3\connectionpool.py", line 714, in urlopen
    httplib_response = self._make_request(
  File "D:\conda\envs\bishespider\lib\site-packages\urllib3\connectionpool.py", line 466, in _make_request
    six.raise_from(e, None)
  File "<string>", line 3, in raise_from
  File "D:\conda\envs\bishespider\lib\site-packages\urllib3\connectionpool.py", line 461, in _make_request
    httplib_response = conn.getresponse()
  File "D:\conda\envs\bishespider\lib\http\client.py", line 1348, in getresponse
    response.begin()
  File "D:\conda\envs\bishespider\lib\http\client.py", line 316, in begin
    version, status, reason = self._read_status()
  File "D:\conda\envs\bishespider\lib\http\client.py", line 277, in _read_status
    line = str(self.fp.readline(_MAXLINE + 1), "iso-8859-1")
  File "D:\conda\envs\bishespider\lib\socket.py", line 669, in readinto
    return self._sock.recv_into(b)
ConnectionResetError: [WinError 10054] 远程主机强迫关闭了一个现有的连接。

During handling of the above exception, another exception occurred:

Traceback (most recent call last):
  File "D:\conda\envs\bishespider\lib\site-packages\requests\adapters.py", line 486, in send
    resp = conn.urlopen(
  File "D:\conda\envs\bishespider\lib\site-packages\urllib3\connectionpool.py", line 798, in urlopen
    retries = retries.increment(
  File "D:\conda\envs\bishespider\lib\site-packages\urllib3\util\retry.py", line 550, in increment
    raise six.reraise(type(error), error, _stacktrace)
  File "D:\conda\envs\bishespider\lib\site-packages\urllib3\packages\six.py", line 769, in reraise
    raise value.with_traceback(tb)
  File "D:\conda\envs\bishespider\lib\site-packages\urllib3\connectionpool.py", line 714, in urlopen
    httplib_response = self._make_request(
  File "D:\conda\envs\bishespider\lib\site-packages\urllib3\connectionpool.py", line 466, in _make_request
    six.raise_from(e, None)
  File "<string>", line 3, in raise_from
  File "D:\conda\envs\bishespider\lib\site-packages\urllib3\connectionpool.py", line 461, in _make_request
    httplib_response = conn.getresponse()
  File "D:\conda\envs\bishespider\lib\http\client.py", line 1348, in getresponse
    response.begin()
  File "D:\conda\envs\bishespider\lib\http\client.py", line 316, in begin
    version, status, reason = self._read_status()
  File "D:\conda\envs\bishespider\lib\http\client.py", line 277, in _read_status
    line = str(self.fp.readline(_MAXLINE + 1), "iso-8859-1")
  File "D:\conda\envs\bishespider\lib\socket.py", line 669, in readinto
    return self._sock.recv_into(b)
urllib3.exceptions.ProtocolError: ('Connection aborted.', ConnectionResetError(10054, '远程主机强迫关闭了一个现有的连接。', None, 10054, None))

During handling of the above exception, another exception occurred:

Traceback (most recent call last):
  File "D:\conda\envs\bishespider\lib\site-packages\gerapy\server\core\utils.py", line 562, in wrapper
    result = func(*args, **kwargs)
  File "D:\conda\envs\bishespider\lib\site-packages\django\views\decorators\csrf.py", line 54, in wrapped_view
    return view_func(*args, **kwargs)
  File "D:\conda\envs\bishespider\lib\site-packages\django\views\generic\base.py", line 71, in view
    return self.dispatch(request, *args, **kwargs)
  File "D:\conda\envs\bishespider\lib\site-packages\rest_framework\views.py", line 509, in dispatch
    response = self.handle_exception(exc)
  File "D:\conda\envs\bishespider\lib\site-packages\rest_framework\views.py", line 469, in handle_exception
    self.raise_uncaught_exception(exc)
  File "D:\conda\envs\bishespider\lib\site-packages\rest_framework\views.py", line 480, in raise_uncaught_exception
    raise exc
  File "D:\conda\envs\bishespider\lib\site-packages\rest_framework\views.py", line 506, in dispatch
    response = handler(request, *args, **kwargs)
  File "D:\conda\envs\bishespider\lib\site-packages\rest_framework\decorators.py", line 50, in handler
    return func(*args, **kwargs)
  File "D:\conda\envs\bishespider\lib\site-packages\gerapy\server\core\views.py", line 227, in project_list
    projects = scrapyd.list_projects()
  File "D:\conda\envs\bishespider\lib\site-packages\scrapyd_api\wrapper.py", line 148, in list_projects
    json = self.client.get(url, timeout=self.timeout)
  File "D:\conda\envs\bishespider\lib\site-packages\requests\sessions.py", line 602, in get
    return self.request("GET", url, **kwargs)
  File "D:\conda\envs\bishespider\lib\site-packages\scrapyd_api\client.py", line 37, in request
    response = super(Client, self).request(*args, **kwargs)
  File "D:\conda\envs\bishespider\lib\site-packages\requests\sessions.py", line 589, in request
    resp = self.send(prep, **send_kwargs)
  File "D:\conda\envs\bishespider\lib\site-packages\requests\sessions.py", line 703, in send
    r = adapter.send(request, **kwargs)
  File "D:\conda\envs\bishespider\lib\site-packages\requests\adapters.py", line 501, in send
    raise ConnectionError(err, request=request)
requests.exceptions.ConnectionError: ('Connection aborted.', ConnectionResetError(10054, '远程主机强迫关闭了一个现有的连接。', None, 10054, None))
ERROR - 2023-10-13 17:30:52,703 - process: 11640 - utils.py - gerapy.server.core.utils - 564 - utils - ('Connection aborted.', ConnectionResetError(10054, '远程主机强迫关闭了一个现有的连接。', None, 10054, None))
Traceback (most recent call last):
  File "D:\conda\envs\bishespider\lib\site-packages\urllib3\connectionpool.py", line 714, in urlopen
    httplib_response = self._make_request(
  File "D:\conda\envs\bishespider\lib\site-packages\urllib3\connectionpool.py", line 466, in _make_request
    six.raise_from(e, None)
  File "<string>", line 3, in raise_from
  File "D:\conda\envs\bishespider\lib\site-packages\urllib3\connectionpool.py", line 461, in _make_request
    httplib_response = conn.getresponse()
  File "D:\conda\envs\bishespider\lib\http\client.py", line 1348, in getresponse
    response.begin()
  File "D:\conda\envs\bishespider\lib\http\client.py", line 316, in begin
    version, status, reason = self._read_status()
  File "D:\conda\envs\bishespider\lib\http\client.py", line 277, in _read_status
    line = str(self.fp.readline(_MAXLINE + 1), "iso-8859-1")
  File "D:\conda\envs\bishespider\lib\socket.py", line 669, in readinto
    return self._sock.recv_into(b)
ConnectionResetError: [WinError 10054] 远程主机强迫关闭了一个现有的连接。

During handling of the above exception, another exception occurred:

Traceback (most recent call last):
  File "D:\conda\envs\bishespider\lib\site-packages\requests\adapters.py", line 486, in send
    resp = conn.urlopen(
  File "D:\conda\envs\bishespider\lib\site-packages\urllib3\connectionpool.py", line 798, in urlopen
    retries = retries.increment(
  File "D:\conda\envs\bishespider\lib\site-packages\urllib3\util\retry.py", line 550, in increment
    raise six.reraise(type(error), error, _stacktrace)
  File "D:\conda\envs\bishespider\lib\site-packages\urllib3\packages\six.py", line 769, in reraise
    raise value.with_traceback(tb)
  File "D:\conda\envs\bishespider\lib\site-packages\urllib3\connectionpool.py", line 714, in urlopen
    httplib_response = self._make_request(
  File "D:\conda\envs\bishespider\lib\site-packages\urllib3\connectionpool.py", line 466, in _make_request
    six.raise_from(e, None)
  File "<string>", line 3, in raise_from
  File "D:\conda\envs\bishespider\lib\site-packages\urllib3\connectionpool.py", line 461, in _make_request
    httplib_response = conn.getresponse()
  File "D:\conda\envs\bishespider\lib\http\client.py", line 1348, in getresponse
    response.begin()
  File "D:\conda\envs\bishespider\lib\http\client.py", line 316, in begin
    version, status, reason = self._read_status()
  File "D:\conda\envs\bishespider\lib\http\client.py", line 277, in _read_status
    line = str(self.fp.readline(_MAXLINE + 1), "iso-8859-1")
  File "D:\conda\envs\bishespider\lib\socket.py", line 669, in readinto
    return self._sock.recv_into(b)
urllib3.exceptions.ProtocolError: ('Connection aborted.', ConnectionResetError(10054, '远程主机强迫关闭了一个现有的连接。', None, 10054, None))

During handling of the above exception, another exception occurred:

Traceback (most recent call last):
  File "D:\conda\envs\bishespider\lib\site-packages\gerapy\server\core\utils.py", line 562, in wrapper
    result = func(*args, **kwargs)
  File "D:\conda\envs\bishespider\lib\site-packages\django\views\decorators\csrf.py", line 54, in wrapped_view
    return view_func(*args, **kwargs)
  File "D:\conda\envs\bishespider\lib\site-packages\django\views\generic\base.py", line 71, in view
    return self.dispatch(request, *args, **kwargs)
  File "D:\conda\envs\bishespider\lib\site-packages\rest_framework\views.py", line 509, in dispatch
    response = self.handle_exception(exc)
  File "D:\conda\envs\bishespider\lib\site-packages\rest_framework\views.py", line 469, in handle_exception
    self.raise_uncaught_exception(exc)
  File "D:\conda\envs\bishespider\lib\site-packages\rest_framework\views.py", line 480, in raise_uncaught_exception
    raise exc
  File "D:\conda\envs\bishespider\lib\site-packages\rest_framework\views.py", line 506, in dispatch
    response = handler(request, *args, **kwargs)
  File "D:\conda\envs\bishespider\lib\site-packages\rest_framework\decorators.py", line 50, in handler
    return func(*args, **kwargs)
  File "D:\conda\envs\bishespider\lib\site-packages\gerapy\server\core\views.py", line 227, in project_list
    projects = scrapyd.list_projects()
  File "D:\conda\envs\bishespider\lib\site-packages\scrapyd_api\wrapper.py", line 148, in list_projects
    json = self.client.get(url, timeout=self.timeout)
  File "D:\conda\envs\bishespider\lib\site-packages\requests\sessions.py", line 602, in get
    return self.request("GET", url, **kwargs)
  File "D:\conda\envs\bishespider\lib\site-packages\scrapyd_api\client.py", line 37, in request
    response = super(Client, self).request(*args, **kwargs)
  File "D:\conda\envs\bishespider\lib\site-packages\requests\sessions.py", line 589, in request
    resp = self.send(prep, **send_kwargs)
  File "D:\conda\envs\bishespider\lib\site-packages\requests\sessions.py", line 703, in send
    r = adapter.send(request, **kwargs)
  File "D:\conda\envs\bishespider\lib\site-packages\requests\adapters.py", line 501, in send
    raise ConnectionError(err, request=request)
requests.exceptions.ConnectionError: ('Connection aborted.', ConnectionResetError(10054, '远程主机强迫关闭了一个现有的连接。', None, 10054, None))
ERROR - 2023-10-13 17:30:52,703 - process: 11640 - utils.py - gerapy.server.core.utils - 564 - utils - ('Connection aborted.', ConnectionResetError(10054, '远程主机强迫关闭了一个现有的连接。', None, 10054, None))
Traceback (most recent call last):
  File "D:\conda\envs\bishespider\lib\site-packages\urllib3\connectionpool.py", line 714, in urlopen
    httplib_response = self._make_request(
  File "D:\conda\envs\bishespider\lib\site-packages\urllib3\connectionpool.py", line 466, in _make_request
    six.raise_from(e, None)
  File "<string>", line 3, in raise_from
  File "D:\conda\envs\bishespider\lib\site-packages\urllib3\connectionpool.py", line 461, in _make_request
    httplib_response = conn.getresponse()
  File "D:\conda\envs\bishespider\lib\http\client.py", line 1348, in getresponse
    response.begin()
  File "D:\conda\envs\bishespider\lib\http\client.py", line 316, in begin
    version, status, reason = self._read_status()
  File "D:\conda\envs\bishespider\lib\http\client.py", line 277, in _read_status
    line = str(self.fp.readline(_MAXLINE + 1), "iso-8859-1")
  File "D:\conda\envs\bishespider\lib\socket.py", line 669, in readinto
    return self._sock.recv_into(b)
ConnectionResetError: [WinError 10054] 远程主机强迫关闭了一个现有的连接。

During handling of the above exception, another exception occurred:

Traceback (most recent call last):
  File "D:\conda\envs\bishespider\lib\site-packages\requests\adapters.py", line 486, in send
    resp = conn.urlopen(
  File "D:\conda\envs\bishespider\lib\site-packages\urllib3\connectionpool.py", line 798, in urlopen
    retries = retries.increment(
  File "D:\conda\envs\bishespider\lib\site-packages\urllib3\util\retry.py", line 550, in increment
    raise six.reraise(type(error), error, _stacktrace)
  File "D:\conda\envs\bishespider\lib\site-packages\urllib3\packages\six.py", line 769, in reraise
    raise value.with_traceback(tb)
  File "D:\conda\envs\bishespider\lib\site-packages\urllib3\connectionpool.py", line 714, in urlopen
    httplib_response = self._make_request(
  File "D:\conda\envs\bishespider\lib\site-packages\urllib3\connectionpool.py", line 466, in _make_request
    six.raise_from(e, None)
  File "<string>", line 3, in raise_from
  File "D:\conda\envs\bishespider\lib\site-packages\urllib3\connectionpool.py", line 461, in _make_request
    httplib_response = conn.getresponse()
  File "D:\conda\envs\bishespider\lib\http\client.py", line 1348, in getresponse
    response.begin()
  File "D:\conda\envs\bishespider\lib\http\client.py", line 316, in begin
    version, status, reason = self._read_status()
  File "D:\conda\envs\bishespider\lib\http\client.py", line 277, in _read_status
    line = str(self.fp.readline(_MAXLINE + 1), "iso-8859-1")
  File "D:\conda\envs\bishespider\lib\socket.py", line 669, in readinto
    return self._sock.recv_into(b)
urllib3.exceptions.ProtocolError: ('Connection aborted.', ConnectionResetError(10054, '远程主机强迫关闭了一个现有的连接。', None, 10054, None))

During handling of the above exception, another exception occurred:

Traceback (most recent call last):
  File "D:\conda\envs\bishespider\lib\site-packages\gerapy\server\core\utils.py", line 562, in wrapper
    result = func(*args, **kwargs)
  File "D:\conda\envs\bishespider\lib\site-packages\django\views\decorators\csrf.py", line 54, in wrapped_view
    return view_func(*args, **kwargs)
  File "D:\conda\envs\bishespider\lib\site-packages\django\views\generic\base.py", line 71, in view
    return self.dispatch(request, *args, **kwargs)
  File "D:\conda\envs\bishespider\lib\site-packages\rest_framework\views.py", line 509, in dispatch
    response = self.handle_exception(exc)
  File "D:\conda\envs\bishespider\lib\site-packages\rest_framework\views.py", line 469, in handle_exception
    self.raise_uncaught_exception(exc)
  File "D:\conda\envs\bishespider\lib\site-packages\rest_framework\views.py", line 480, in raise_uncaught_exception
    raise exc
  File "D:\conda\envs\bishespider\lib\site-packages\rest_framework\views.py", line 506, in dispatch
    response = handler(request, *args, **kwargs)
  File "D:\conda\envs\bishespider\lib\site-packages\rest_framework\decorators.py", line 50, in handler
    return func(*args, **kwargs)
  File "D:\conda\envs\bishespider\lib\site-packages\gerapy\server\core\views.py", line 690, in job_list
    result = scrapyd.list_jobs(project_name)
  File "D:\conda\envs\bishespider\lib\site-packages\scrapyd_api\wrapper.py", line 139, in list_jobs
    jobs = self.client.get(url, params=params, timeout=self.timeout)
  File "D:\conda\envs\bishespider\lib\site-packages\requests\sessions.py", line 602, in get
    return self.request("GET", url, **kwargs)
  File "D:\conda\envs\bishespider\lib\site-packages\scrapyd_api\client.py", line 37, in request
    response = super(Client, self).request(*args, **kwargs)
  File "D:\conda\envs\bishespider\lib\site-packages\requests\sessions.py", line 589, in request
    resp = self.send(prep, **send_kwargs)
  File "D:\conda\envs\bishespider\lib\site-packages\requests\sessions.py", line 703, in send
    r = adapter.send(request, **kwargs)
  File "D:\conda\envs\bishespider\lib\site-packages\requests\adapters.py", line 501, in send
    raise ConnectionError(err, request=request)
requests.exceptions.ConnectionError: ('Connection aborted.', ConnectionResetError(10054, '远程主机强迫关闭了一个现有的连接。', None, 10054, None))
ERROR - 2023-10-13 17:30:52,703 - process: 11640 - utils.py - gerapy.server.core.utils - 564 - utils - ('Connection aborted.', ConnectionResetError(10054, '远程主机强迫关闭了一个现有的连接。', None, 10054, None))
Traceback (most recent call last):
  File "D:\conda\envs\bishespider\lib\site-packages\urllib3\connectionpool.py", line 714, in urlopen
    httplib_response = self._make_request(
  File "D:\conda\envs\bishespider\lib\site-packages\urllib3\connectionpool.py", line 466, in _make_request
    six.raise_from(e, None)
  File "<string>", line 3, in raise_from
  File "D:\conda\envs\bishespider\lib\site-packages\urllib3\connectionpool.py", line 461, in _make_request
    httplib_response = conn.getresponse()
  File "D:\conda\envs\bishespider\lib\http\client.py", line 1348, in getresponse
    response.begin()
  File "D:\conda\envs\bishespider\lib\http\client.py", line 316, in begin
    version, status, reason = self._read_status()
  File "D:\conda\envs\bishespider\lib\http\client.py", line 277, in _read_status
    line = str(self.fp.readline(_MAXLINE + 1), "iso-8859-1")
  File "D:\conda\envs\bishespider\lib\socket.py", line 669, in readinto
    return self._sock.recv_into(b)
ConnectionResetError: [WinError 10054] 远程主机强迫关闭了一个现有的连接。

During handling of the above exception, another exception occurred:

Traceback (most recent call last):
  File "D:\conda\envs\bishespider\lib\site-packages\requests\adapters.py", line 486, in send
    resp = conn.urlopen(
  File "D:\conda\envs\bishespider\lib\site-packages\urllib3\connectionpool.py", line 798, in urlopen
    retries = retries.increment(
  File "D:\conda\envs\bishespider\lib\site-packages\urllib3\util\retry.py", line 550, in increment
    raise six.reraise(type(error), error, _stacktrace)
  File "D:\conda\envs\bishespider\lib\site-packages\urllib3\packages\six.py", line 769, in reraise
    raise value.with_traceback(tb)
  File "D:\conda\envs\bishespider\lib\site-packages\urllib3\connectionpool.py", line 714, in urlopen
    httplib_response = self._make_request(
  File "D:\conda\envs\bishespider\lib\site-packages\urllib3\connectionpool.py", line 466, in _make_request
    six.raise_from(e, None)
  File "<string>", line 3, in raise_from
  File "D:\conda\envs\bishespider\lib\site-packages\urllib3\connectionpool.py", line 461, in _make_request
    httplib_response = conn.getresponse()
  File "D:\conda\envs\bishespider\lib\http\client.py", line 1348, in getresponse
    response.begin()
  File "D:\conda\envs\bishespider\lib\http\client.py", line 316, in begin
    version, status, reason = self._read_status()
  File "D:\conda\envs\bishespider\lib\http\client.py", line 277, in _read_status
    line = str(self.fp.readline(_MAXLINE + 1), "iso-8859-1")
  File "D:\conda\envs\bishespider\lib\socket.py", line 669, in readinto
    return self._sock.recv_into(b)
urllib3.exceptions.ProtocolError: ('Connection aborted.', ConnectionResetError(10054, '远程主机强迫关闭了一个现有的连接。', None, 10054, None))

During handling of the above exception, another exception occurred:

Traceback (most recent call last):
  File "D:\conda\envs\bishespider\lib\site-packages\gerapy\server\core\utils.py", line 562, in wrapper
    result = func(*args, **kwargs)
  File "D:\conda\envs\bishespider\lib\site-packages\django\views\decorators\csrf.py", line 54, in wrapped_view
    return view_func(*args, **kwargs)
  File "D:\conda\envs\bishespider\lib\site-packages\django\views\generic\base.py", line 71, in view
    return self.dispatch(request, *args, **kwargs)
  File "D:\conda\envs\bishespider\lib\site-packages\rest_framework\views.py", line 509, in dispatch
    response = self.handle_exception(exc)
  File "D:\conda\envs\bishespider\lib\site-packages\rest_framework\views.py", line 469, in handle_exception
    self.raise_uncaught_exception(exc)
  File "D:\conda\envs\bishespider\lib\site-packages\rest_framework\views.py", line 480, in raise_uncaught_exception
    raise exc
  File "D:\conda\envs\bishespider\lib\site-packages\rest_framework\views.py", line 506, in dispatch
    response = handler(request, *args, **kwargs)
  File "D:\conda\envs\bishespider\lib\site-packages\rest_framework\decorators.py", line 50, in handler
    return func(*args, **kwargs)
  File "D:\conda\envs\bishespider\lib\site-packages\gerapy\server\core\views.py", line 690, in job_list
    result = scrapyd.list_jobs(project_name)
  File "D:\conda\envs\bishespider\lib\site-packages\scrapyd_api\wrapper.py", line 139, in list_jobs
    jobs = self.client.get(url, params=params, timeout=self.timeout)
  File "D:\conda\envs\bishespider\lib\site-packages\requests\sessions.py", line 602, in get
    return self.request("GET", url, **kwargs)
  File "D:\conda\envs\bishespider\lib\site-packages\scrapyd_api\client.py", line 37, in request
    response = super(Client, self).request(*args, **kwargs)
  File "D:\conda\envs\bishespider\lib\site-packages\requests\sessions.py", line 589, in request
    resp = self.send(prep, **send_kwargs)
  File "D:\conda\envs\bishespider\lib\site-packages\requests\sessions.py", line 703, in send
    r = adapter.send(request, **kwargs)
  File "D:\conda\envs\bishespider\lib\site-packages\requests\adapters.py", line 501, in send
    raise ConnectionError(err, request=request)
requests.exceptions.ConnectionError: ('Connection aborted.', ConnectionResetError(10054, '远程主机强迫关闭了一个现有的连接。', None, 10054, None))
ERROR - 2023-10-13 17:30:52,703 - process: 11640 - utils.py - gerapy.server.core.utils - 564 - utils - ('Connection aborted.', ConnectionResetError(10054, '远程主机强迫关闭了一个现有的连接。', None, 10054, None))
Traceback (most recent call last):
  File "D:\conda\envs\bishespider\lib\site-packages\urllib3\connectionpool.py", line 714, in urlopen
    httplib_response = self._make_request(
  File "D:\conda\envs\bishespider\lib\site-packages\urllib3\connectionpool.py", line 466, in _make_request
    six.raise_from(e, None)
  File "<string>", line 3, in raise_from
  File "D:\conda\envs\bishespider\lib\site-packages\urllib3\connectionpool.py", line 461, in _make_request
    httplib_response = conn.getresponse()
  File "D:\conda\envs\bishespider\lib\http\client.py", line 1348, in getresponse
    response.begin()
  File "D:\conda\envs\bishespider\lib\http\client.py", line 316, in begin
    version, status, reason = self._read_status()
  File "D:\conda\envs\bishespider\lib\http\client.py", line 277, in _read_status
    line = str(self.fp.readline(_MAXLINE + 1), "iso-8859-1")
  File "D:\conda\envs\bishespider\lib\socket.py", line 669, in readinto
    return self._sock.recv_into(b)
ConnectionResetError: [WinError 10054] 远程主机强迫关闭了一个现有的连接。

During handling of the above exception, another exception occurred:

Traceback (most recent call last):
  File "D:\conda\envs\bishespider\lib\site-packages\requests\adapters.py", line 486, in send
    resp = conn.urlopen(
  File "D:\conda\envs\bishespider\lib\site-packages\urllib3\connectionpool.py", line 798, in urlopen
    retries = retries.increment(
  File "D:\conda\envs\bishespider\lib\site-packages\urllib3\util\retry.py", line 550, in increment
    raise six.reraise(type(error), error, _stacktrace)
  File "D:\conda\envs\bishespider\lib\site-packages\urllib3\packages\six.py", line 769, in reraise
    raise value.with_traceback(tb)
  File "D:\conda\envs\bishespider\lib\site-packages\urllib3\connectionpool.py", line 714, in urlopen
    httplib_response = self._make_request(
  File "D:\conda\envs\bishespider\lib\site-packages\urllib3\connectionpool.py", line 466, in _make_request
    six.raise_from(e, None)
  File "<string>", line 3, in raise_from
  File "D:\conda\envs\bishespider\lib\site-packages\urllib3\connectionpool.py", line 461, in _make_request
    httplib_response = conn.getresponse()
  File "D:\conda\envs\bishespider\lib\http\client.py", line 1348, in getresponse
    response.begin()
  File "D:\conda\envs\bishespider\lib\http\client.py", line 316, in begin
    version, status, reason = self._read_status()
  File "D:\conda\envs\bishespider\lib\http\client.py", line 277, in _read_status
    line = str(self.fp.readline(_MAXLINE + 1), "iso-8859-1")
  File "D:\conda\envs\bishespider\lib\socket.py", line 669, in readinto
    return self._sock.recv_into(b)
urllib3.exceptions.ProtocolError: ('Connection aborted.', ConnectionResetError(10054, '远程主机强迫关闭了一个现有的连接。', None, 10054, None))

During handling of the above exception, another exception occurred:

Traceback (most recent call last):
  File "D:\conda\envs\bishespider\lib\site-packages\gerapy\server\core\utils.py", line 562, in wrapper
    result = func(*args, **kwargs)
  File "D:\conda\envs\bishespider\lib\site-packages\django\views\decorators\csrf.py", line 54, in wrapped_view
    return view_func(*args, **kwargs)
  File "D:\conda\envs\bishespider\lib\site-packages\django\views\generic\base.py", line 71, in view
    return self.dispatch(request, *args, **kwargs)
  File "D:\conda\envs\bishespider\lib\site-packages\rest_framework\views.py", line 509, in dispatch
    response = self.handle_exception(exc)
  File "D:\conda\envs\bishespider\lib\site-packages\rest_framework\views.py", line 469, in handle_exception
    self.raise_uncaught_exception(exc)
  File "D:\conda\envs\bishespider\lib\site-packages\rest_framework\views.py", line 480, in raise_uncaught_exception
    raise exc
  File "D:\conda\envs\bishespider\lib\site-packages\rest_framework\views.py", line 506, in dispatch
    response = handler(request, *args, **kwargs)
  File "D:\conda\envs\bishespider\lib\site-packages\rest_framework\decorators.py", line 50, in handler
    return func(*args, **kwargs)
  File "D:\conda\envs\bishespider\lib\site-packages\gerapy\server\core\views.py", line 227, in project_list
    projects = scrapyd.list_projects()
  File "D:\conda\envs\bishespider\lib\site-packages\scrapyd_api\wrapper.py", line 148, in list_projects
    json = self.client.get(url, timeout=self.timeout)
  File "D:\conda\envs\bishespider\lib\site-packages\requests\sessions.py", line 602, in get
    return self.request("GET", url, **kwargs)
  File "D:\conda\envs\bishespider\lib\site-packages\scrapyd_api\client.py", line 37, in request
    response = super(Client, self).request(*args, **kwargs)
  File "D:\conda\envs\bishespider\lib\site-packages\requests\sessions.py", line 589, in request
    resp = self.send(prep, **send_kwargs)
  File "D:\conda\envs\bishespider\lib\site-packages\requests\sessions.py", line 703, in send
    r = adapter.send(request, **kwargs)
  File "D:\conda\envs\bishespider\lib\site-packages\requests\adapters.py", line 501, in send
    raise ConnectionError(err, request=request)
requests.exceptions.ConnectionError: ('Connection aborted.', ConnectionResetError(10054, '远程主机强迫关闭了一个现有的连接。', None, 10054, None))
